<?xml version="1.0"?>
<robot name="kart">

    <material name="gray">
        <color rgba="0.3 0.3 0.3 1"/>
    </material>

  <link name="body">
    <visual>
      <geometry>
        <box size="0.25 0.25 0.1"/>
      </geometry>
      <origin rpy="0 0 0" xyz="0 0.00 0.0"/>
      <material name="gray"/>
    </visual>
    <collision>
      <geometry>
        <box size="0.25 0.25 0.1"/>
      </geometry>
      <origin rpy="0 0 0" xyz="0 0.0 0.0"/>
      <contact_coefficents mu="0.0" kp="0.0" kd="0.0"/>
    </collision>
    <inertial>
      <mass value="0.8"/>
      <inertia ixx="0.001" ixy="0.0" ixz="0.0" iyy="0.001" iyz="0.0" izz="0.001"/>
      <origin rpy="0 0 0" xyz="0 0.0 0.3"/>
    </inertial>
  </link>

  <link name="tongue">
    <visual>
      <geometry>
        <box size="0.1 0.1 0.1"/>
      </geometry>
      <origin rpy="0 0 0" xyz="0 0.00 0.0"/>
      <material name="gray"/>
    </visual>
    <collision>
      <geometry>
        <box size="0.075 0.075 0.1"/>
      </geometry>
      <origin rpy="0 0 0" xyz="0 0.0 0.0"/>
      <contact_coefficents mu="0.0" kp="0.0" kd="0.0"/>
    </collision>
    <inertial>
      <mass value="0.8"/>
      <inertia ixx="0.001" ixy="0.0" ixz="0.0" iyy="0.001" iyz="0.0" izz="0.001"/>
      <origin rpy="0 0 0" xyz="0 0.0 0.3"/>
    </inertial>
  </link>


  <link name="r_wheel">
    <visual>
      <geometry>
        <cylinder length="0.1" radius="0.075"/>
      </geometry>
      <origin rpy="0 1.5707963 0" xyz="0 0 0"/>
      <material name="gray"/>
    </visual>
    <collision>
      <geometry>
        <cylinder length="0.1" radius="0.075"/>
      </geometry>
      <origin rpy="0 1.5707963 0" xyz="0 0 0"/>
      <contact_coefficients mu="0.8" />
    </collision>
    <inertial>
      <mass value="0.1"/>
      <inertia ixx="0.0001" ixy="0.0" ixz="0.0" iyy="0.0001" iyz="0.0" izz="0.0001"/>
      <origin rpy="0 0 0" xyz="0 0 0"/>
    </inertial>
  </link>

  <link name="b_wheel">
    <visual>
      <geometry>
        <cylinder length="0.1" radius="0.075"/>
      </geometry>
      <origin rpy="0 1.5707963 0" xyz="0 0 0"/>
      <material name="gray"/>
    </visual>
    <collision>
      <geometry>
        <cylinder length="0.1" radius="0.075"/>
      </geometry>
      <origin rpy="0 1.5707963 0" xyz="0 0 0"/>
      <contact_coefficients mu="0.8" />
    </collision>
    <inertial>
      <mass value="0.1"/>
      <inertia ixx="0.0001" ixy="0.0" ixz="0.0" iyy="0.0001" iyz="0.0" izz="0.0001"/>
      <origin rpy="0 0 0" xyz="0 0 0"/>
    </inertial>
  </link>

  <link name="l_wheel">
    <visual>
      <geometry>
        <cylinder length="0.1" radius="0.075"/>
      </geometry>
      <origin rpy="0 1.5707963 0" xyz="0 0 0"/>
      <material name="gray"/>
    </visual>
    <collision>
      <geometry>
        <cylinder length="0.1" radius="0.075"/>
      </geometry>
      <origin rpy="0 1.5707963 0" xyz="0 0 0"/>
      <contact_coefficients mu="0.8" />
    </collision>
    <inertial>
      <mass value="0.1"/>
      <inertia ixx="0.0001" ixy="0.0" ixz="0.0" iyy="0.0001" iyz="0.0" izz="0.0001"/>
      <origin rpy="0 0 0" xyz="0 0 0"/>
    </inertial>
  </link>

  <joint name="body_tongue" type="continuous">
    <parent link="body"/>
    <child link="tongue"/>
    <axis xyz="-1 0 0"/>
    <limit effort="0.0" lower="0.0" upper="0.0" velocity="0.0"/>
    <origin rpy="0 0 0" xyz="0. 0.125 0.0"/>
  </joint>

  <joint name="body_l_wheel" type="continuous">
    <parent link="body"/>
    <child link="l_wheel"/>
    <axis xyz="-1 0 0"/>
    <limit effort="1000.0" lower="0.0" upper="0.548" velocity="0.0"/>
    <origin rpy="0 0 0" xyz="-0.175 0.05 0.0"/>
  </joint>

  <joint name="body_r_wheel" type="continuous">
    <parent link="body"/>
    <child link="r_wheel"/>
    <axis xyz="1 0 0"/>
   <limit effort="1000.0" lower="0.0" upper="0.548" velocity="0.0"/>
   <origin rpy="0 0 0" xyz="0.175 0.05 0.0"/>
  </joint>

  <joint name="body_b_wheel" type="continuous">
    <parent link="body"/>
    <child link="b_wheel"/>
    <axis xyz="1 0 0"/>
   <limit effort="1000.0" lower="0.0" upper="0.548" velocity="0.0"/>
   <origin rpy="0 0 0" xyz="0.0 -0.175 0.0"/>
  </joint>
</robot>
