?xml version="1.0"?>
<robot name="puck">

    <material name="gray">
        <color rgba="0.3 0.3 0.3 1"/>
    </material>

  <link name="puck">
    <visual>
      <geometry>
        <cylinder length="0.05"  radius="0.1"/>
      </geometry>
      <origin rpy="0 0 0" xyz="0 0.00 0.0"/>
      <material name="gray"/>
    </visual>
    <collision>
      <geometry>
        <cylinder length="0.05"  radius="0.1"/>
      </geometry>
      <origin rpy="0 0 0" xyz="0 0.0 0.0"/>
      <contact_coefficents mu="0.0" kp="0.0" kd="0.0"/>
    </collision>
    <inertial>
      <mass value="0.3"/>
      <inertia ixx="0.001" ixy="0.0" ixz="0.0" iyy="0.001" iyz="0.0" izz="0.001"/>
      <origin rpy="0 0 0" xyz="0 0.0 0.3"/>
    </inertial>
  </link>

  <link name="face">
    <visual>
      <geometry>
        <box size="0.1 0.2 0.05"/>
      </geometry>
      <origin rpy="0 0 0" xyz="0.05 0.00 0.0"/>
      <material name="gray"/>
    </visual>
    <collision>
      <geometry>
        <box size="0.1 0.2 0.05"/>
      </geometry>
      <origin rpy="0 0 0" xyz="0.05 0.0 0.0"/>
      <contact_coefficents mu="0.0" kp="0.0" kd="0.0"/>
    </collision>
    <inertial>
      <mass value="0.3"/>
      <inertia ixx="0.001" ixy="0.0" ixz="0.0" iyy="0.001" iyz="0.0" izz="0.001"/>
      <origin rpy="0 0 0" xyz="0 0.0 0.0"/>
    </inertial>
  </link>

  <joint name="puck_face" type="continuous">
    <parent link="puck"/>
    <child link="face"/>
    <axis xyz="-1 0 0"/>
    <limit effort="0.0" lower="0.0" upper="0.0" velocity="0.0"/>
    <origin rpy="0 0 0" xyz="0.0 0.0 0.0"/>
  </joint>



</robot>
